#How to handle exceptions:
import os
from colorama import Fore, Back, Style
os.system("cls || clear")

diccionario  = dict(a=1, b=2)

try:
    resultado = 14 / 0
except ZeroDivisionError: #Recogemos los errores desde el m√°s particular (si los conocemos), al m√°s general
    print (Fore.RED + "¬°El divisor no puede ser cero!" + Style.RESET_ALL)
except Exception as ex:
    print(Fore.LIGHTRED_EX + "Ha habido un horror:üò± "+ Style.RESET_ALL + Style.BRIGHT + f"{ex}")

try:
    resultado = 14 / "b"
except Exception as ex:
    print(Fore.LIGHTRED_EX + "Ha habido un horror:üò± "+ Style.RESET_ALL + Style.BRIGHT + f"{ex}" + Style.RESET_ALL)

#Luego, podemos poner:
    
try:
    resultado = 14 / "b"
except TypeError as tex:
    print(Style.BRIGHT + f"{tex}")

#Puedo englobar las excepciones:
try:
    resultado = 14 / "b"
    print(resultado)
except (ZeroDivisionError, TypeError): #OjO: han de estar entre par√©ntesis
    print("El error es de tipo numerico")

try:
    #resultado = 14 / 0
    #print(resultado)
    data = diccionario["c"]

except (ZeroDivisionError, TypeError):
    print("El error es de tipo numerico")
except Exception as ex:
    print(f"Ha habido un error: {ex}")

try:
    #resultado = 14 / 0
    #print(resultado)
    data = diccionario["c"]

except (ZeroDivisionError, TypeError):
    print("El error es de tipo numerico")
except KeyError as kex:
    print(f"Clave inexistente:{kex}")
except Exception as ex:
    print(f"Ha habido un error: {ex}")

# def convertir_a_entero(data:str) -> int:
#     # try:
#         return int(data)
#     # except:
# resultado_entero = convertir_a_entero("p")
# print(resultado_entero)
# #Mirando el error arrojado lo a√±ado a except:

def convertir_a_entero(data:str) -> int:
    resultado = None
    try:
        return int(data)
    except ValueError: #Capturo la excepci√≥n y as√≠ no peta el programa. Me devolver√° None y ya s√© que ha habido un error
        pass #No hace nada en caso de error porque ya he asignado por defecto el valor None si hay error
    return resultado

resultado_entero = convertir_a_entero("P")
#print(resultado_entero)
print(resultado_entero if resultado_entero else "Problema al convertir üò§")

diccionario = {
    "111H": "Juan",
    "222H": "Paloma"
}

try:
    del diccionario
    diccionario["111H"] = "Miguel"
except Exception:
    print("Buah üò§")

#diccionario["111H"] = "Miguel" S√≥lo lo hacemos para capturar el error. Una vez capturado:
    
try:
    diccionario["111H"] = "Miguel"
except NameError:
    print("Ese diccionario no existe üò§")
except Exception:
    print ("Error general")
else:
    print("Se ha completado satisfactoriammente la operaci√≥n") #Esto s√≥lo se ejecuta si el try no dio error.
    #Esto podr√≠a ser √∫ltil cada vez que modifiquemos una base de datos, pues es importante saber si las transacciones se completan (por citar un ejemplo).
finally:
    print("Operaci√≥n terminada") #Esto se ejecuta tanto cuando hay error como cuando no (try que funcione)